<?xml version="1.0"?>

<robot xmlns:xacro="http://www.ros.org/wiki/xacro" name="healthcare_robot">

<link name="base_link">
  <visual>
    <geometry>
      <box size="0.4 0.3 0.1"/>
    </geometry>
  </visual>

  <collision>
    <geometry>
      <box size="0.4 0.3 0.1"/>
    </geometry>
  </collision>

  <inertial>
    <mass value="5.0"/>
    <origin xyz="0 0 0"/>
    <inertia ixx="0.1" ixy="0" ixz="0"
             iyy="0.1" iyz="0"
             izz="0.1"/>
  </inertial>
</link>


<!-- LEFT WHEEL -->

<link name="left_wheel">
  <visual>
    <geometry>
      <cylinder radius="0.05" length="0.02"/>
    </geometry>
  </visual>
</link>

<joint name="left_wheel_joint" type="continuous">
  <parent link="base_link"/>
  <child link="left_wheel"/>
  <origin xyz="0 0.15 0"/>
  <axis xyz="0 1 0"/>
</joint>


<!-- RIGHT WHEEL -->

<link name="right_wheel">
  <visual>
    <geometry>
      <cylinder radius="0.05" length="0.02"/>
    </geometry>
  </visual>
</link>

<joint name="right_wheel_joint" type="continuous">
  <parent link="base_link"/>
  <child link="right_wheel"/>
  <origin xyz="0 -0.15 0"/>
  <axis xyz="0 1 0"/>
</joint>


<!-- LIDAR -->

<link name="laser_link">
  <visual>
    <geometry>
      <cylinder radius="0.03" length="0.05"/>
    </geometry>
  </visual>
</link>

<joint name="laser_joint" type="fixed">
  <parent link="base_link"/>
  <child link="laser_link"/>
  <origin xyz="0 0 0.2"/>
</joint>


<!-- DEPTH CAMERA -->

<link name="camera_link">
  <visual>
    <geometry>
      <box size="0.05 0.05 0.05"/>
    </geometry>
  </visual>
</link>

<joint name="camera_joint" type="fixed">
  <parent link="base_link"/>
  <child link="camera_link"/>
  <origin xyz="0.15 0 0.2"/>
</joint>


<gazebo reference="camera_link">
  <sensor name="depth_camera" type="depth">

    <update_rate>30</update_rate>

    <camera>
      <horizontal_fov>1.57</horizontal_fov>

      <image>
        <width>640</width>
        <height>480</height>
        <format>R8G8B8</format>
      </image>

      <clip>
        <near>0.1</near>
        <far>10.0</far>
      </clip>

    </camera>

    <plugin name="camera_controller" filename="libgazebo_ros_camera.so">
      <frame_name>camera_link</frame_name>
    </plugin>

  </sensor>
</gazebo>


<!-- DIFFERENTIAL DRIVE -->

<gazebo>
  <plugin name="diff_drive" filename="libgazebo_ros_diff_drive.so">

    <left_joint>left_wheel_joint</left_joint>
    <right_joint>right_wheel_joint</right_joint>

    <wheel_separation>0.30</wheel_separation>
    <wheel_diameter>0.10</wheel_diameter>

    <publish_odom>true</publish_odom>
    <publish_odom_tf>true</publish_odom_tf>

    <command_topic>cmd_vel</command_topic>
    <odometry_topic>odom</odometry_topic>

  </plugin>
</gazebo>

</robot>
